[2024-07-03T19:16:09.972+0000] {local_task_job_runner.py:120} INFO - ::group::Pre task execution logs
[2024-07-03T19:16:09.999+0000] {taskinstance.py:2076} INFO - Dependencies all met for dep_context=non-requeueable deps ti=<TaskInstance: first_dag.first_task scheduled__2023-07-08T00:00:00+00:00 [queued]>
[2024-07-03T19:16:10.011+0000] {taskinstance.py:2076} INFO - Dependencies all met for dep_context=requeueable deps ti=<TaskInstance: first_dag.first_task scheduled__2023-07-08T00:00:00+00:00 [queued]>
[2024-07-03T19:16:10.012+0000] {taskinstance.py:2306} INFO - Starting attempt 1 of 6
[2024-07-03T19:16:10.030+0000] {taskinstance.py:2330} INFO - Executing <Task(BashOperator): first_task> on 2023-07-08 00:00:00+00:00
[2024-07-03T19:16:10.037+0000] {warnings.py:112} WARNING - /home/***/.local/lib/python3.12/site-packages/***/task/task_runner/standard_task_runner.py:61: DeprecationWarning: This process (pid=796) is multi-threaded, use of fork() may lead to deadlocks in the child.
  pid = os.fork()

[2024-07-03T19:16:10.039+0000] {standard_task_runner.py:63} INFO - Started process 807 to run task
[2024-07-03T19:16:10.039+0000] {standard_task_runner.py:90} INFO - Running: ['***', 'tasks', 'run', 'first_dag', 'first_task', 'scheduled__2023-07-08T00:00:00+00:00', '--job-id', '135', '--raw', '--subdir', 'DAGS_FOLDER/first_dag.py', '--cfg-path', '/tmp/tmp5944gnql']
[2024-07-03T19:16:10.040+0000] {standard_task_runner.py:91} INFO - Job 135: Subtask first_task
[2024-07-03T19:16:10.094+0000] {task_command.py:426} INFO - Running <TaskInstance: first_dag.first_task scheduled__2023-07-08T00:00:00+00:00 [running]> on host 2a6e93921527
[2024-07-03T19:16:10.184+0000] {taskinstance.py:2648} INFO - Exporting env vars: AIRFLOW_CTX_DAG_OWNER='me' AIRFLOW_CTX_DAG_ID='first_dag' AIRFLOW_CTX_TASK_ID='first_task' AIRFLOW_CTX_EXECUTION_DATE='2023-07-08T00:00:00+00:00' AIRFLOW_CTX_TRY_NUMBER='1' AIRFLOW_CTX_DAG_RUN_ID='scheduled__2023-07-08T00:00:00+00:00'
[2024-07-03T19:16:10.185+0000] {taskinstance.py:430} INFO - ::endgroup::
[2024-07-03T19:16:10.201+0000] {subprocess.py:63} INFO - Tmp dir root location: /tmp
[2024-07-03T19:16:10.202+0000] {subprocess.py:75} INFO - Running command: ['/usr/bin/bash', '-c', 'Hello world, this is the first task']
[2024-07-03T19:16:10.216+0000] {subprocess.py:86} INFO - Output:
[2024-07-03T19:16:10.218+0000] {subprocess.py:93} INFO - /usr/bin/bash: line 1: Hello: command not found
[2024-07-03T19:16:10.219+0000] {subprocess.py:97} INFO - Command exited with return code 127
[2024-07-03T19:16:10.220+0000] {taskinstance.py:441} INFO - ::group::Post task execution logs
[2024-07-03T19:16:10.231+0000] {taskinstance.py:2905} ERROR - Task failed with exception
Traceback (most recent call last):
  File "/home/airflow/.local/lib/python3.12/site-packages/airflow/models/taskinstance.py", line 465, in _execute_task
    result = _execute_callable(context=context, **execute_callable_kwargs)
             ^^^^^^^^^^^^^^^^^^^^^^^^^^^^^^^^^^^^^^^^^^^^^^^^^^^^^^^^^^^^^
  File "/home/airflow/.local/lib/python3.12/site-packages/airflow/models/taskinstance.py", line 432, in _execute_callable
    return execute_callable(context=context, **execute_callable_kwargs)
           ^^^^^^^^^^^^^^^^^^^^^^^^^^^^^^^^^^^^^^^^^^^^^^^^^^^^^^^^^^^^
  File "/home/airflow/.local/lib/python3.12/site-packages/airflow/models/baseoperator.py", line 401, in wrapper
    return func(self, *args, **kwargs)
           ^^^^^^^^^^^^^^^^^^^^^^^^^^^
  File "/home/airflow/.local/lib/python3.12/site-packages/airflow/operators/bash.py", line 243, in execute
    raise AirflowException(
airflow.exceptions.AirflowException: Bash command failed. The command returned a non-zero exit code 127.
[2024-07-03T19:16:10.236+0000] {taskinstance.py:1206} INFO - Marking task as UP_FOR_RETRY. dag_id=first_dag, task_id=first_task, run_id=scheduled__2023-07-08T00:00:00+00:00, execution_date=20230708T000000, start_date=20240703T191610, end_date=20240703T191610
[2024-07-03T19:16:10.313+0000] {standard_task_runner.py:110} ERROR - Failed to execute job 135 for task first_task (Bash command failed. The command returned a non-zero exit code 127.; 807)
[2024-07-03T19:16:10.374+0000] {local_task_job_runner.py:240} INFO - Task exited with return code 1
[2024-07-03T19:16:10.394+0000] {taskinstance.py:3503} INFO - 0 downstream tasks scheduled from follow-on schedule check
[2024-07-03T19:16:10.397+0000] {local_task_job_runner.py:222} INFO - ::endgroup::
[2024-07-03T19:20:58.768+0000] {local_task_job_runner.py:120} INFO - ::group::Pre task execution logs
[2024-07-03T19:20:58.812+0000] {taskinstance.py:2076} INFO - Dependencies all met for dep_context=non-requeueable deps ti=<TaskInstance: first_dag.first_task scheduled__2023-07-08T00:00:00+00:00 [queued]>
[2024-07-03T19:20:58.823+0000] {taskinstance.py:2076} INFO - Dependencies all met for dep_context=requeueable deps ti=<TaskInstance: first_dag.first_task scheduled__2023-07-08T00:00:00+00:00 [queued]>
[2024-07-03T19:20:58.824+0000] {taskinstance.py:2306} INFO - Starting attempt 1 of 6
[2024-07-03T19:20:58.842+0000] {taskinstance.py:2330} INFO - Executing <Task(BashOperator): first_task> on 2023-07-08 00:00:00+00:00
[2024-07-03T19:20:58.849+0000] {warnings.py:112} WARNING - /home/***/.local/lib/python3.12/site-packages/***/task/task_runner/standard_task_runner.py:61: DeprecationWarning: This process (pid=956) is multi-threaded, use of fork() may lead to deadlocks in the child.
  pid = os.fork()

[2024-07-03T19:20:58.851+0000] {standard_task_runner.py:63} INFO - Started process 967 to run task
[2024-07-03T19:20:58.851+0000] {standard_task_runner.py:90} INFO - Running: ['***', 'tasks', 'run', 'first_dag', 'first_task', 'scheduled__2023-07-08T00:00:00+00:00', '--job-id', '167', '--raw', '--subdir', 'DAGS_FOLDER/first_dag.py', '--cfg-path', '/tmp/tmp4aj4hnh1']
[2024-07-03T19:20:58.852+0000] {standard_task_runner.py:91} INFO - Job 167: Subtask first_task
[2024-07-03T19:20:58.907+0000] {task_command.py:426} INFO - Running <TaskInstance: first_dag.first_task scheduled__2023-07-08T00:00:00+00:00 [running]> on host 2a6e93921527
[2024-07-03T19:20:59.014+0000] {taskinstance.py:2648} INFO - Exporting env vars: AIRFLOW_CTX_DAG_OWNER='me' AIRFLOW_CTX_DAG_ID='first_dag' AIRFLOW_CTX_TASK_ID='first_task' AIRFLOW_CTX_EXECUTION_DATE='2023-07-08T00:00:00+00:00' AIRFLOW_CTX_TRY_NUMBER='1' AIRFLOW_CTX_DAG_RUN_ID='scheduled__2023-07-08T00:00:00+00:00'
[2024-07-03T19:20:59.015+0000] {taskinstance.py:430} INFO - ::endgroup::
[2024-07-03T19:20:59.033+0000] {subprocess.py:63} INFO - Tmp dir root location: /tmp
[2024-07-03T19:20:59.042+0000] {subprocess.py:75} INFO - Running command: ['/usr/bin/bash', '-c', 'Hello world, this is the first task']
[2024-07-03T19:20:59.069+0000] {subprocess.py:86} INFO - Output:
[2024-07-03T19:20:59.071+0000] {subprocess.py:93} INFO - /usr/bin/bash: line 1: Hello: command not found
[2024-07-03T19:20:59.072+0000] {subprocess.py:97} INFO - Command exited with return code 127
[2024-07-03T19:20:59.072+0000] {taskinstance.py:441} INFO - ::group::Post task execution logs
[2024-07-03T19:20:59.084+0000] {taskinstance.py:2905} ERROR - Task failed with exception
Traceback (most recent call last):
  File "/home/airflow/.local/lib/python3.12/site-packages/airflow/models/taskinstance.py", line 465, in _execute_task
    result = _execute_callable(context=context, **execute_callable_kwargs)
             ^^^^^^^^^^^^^^^^^^^^^^^^^^^^^^^^^^^^^^^^^^^^^^^^^^^^^^^^^^^^^
  File "/home/airflow/.local/lib/python3.12/site-packages/airflow/models/taskinstance.py", line 432, in _execute_callable
    return execute_callable(context=context, **execute_callable_kwargs)
           ^^^^^^^^^^^^^^^^^^^^^^^^^^^^^^^^^^^^^^^^^^^^^^^^^^^^^^^^^^^^
  File "/home/airflow/.local/lib/python3.12/site-packages/airflow/models/baseoperator.py", line 401, in wrapper
    return func(self, *args, **kwargs)
           ^^^^^^^^^^^^^^^^^^^^^^^^^^^
  File "/home/airflow/.local/lib/python3.12/site-packages/airflow/operators/bash.py", line 243, in execute
    raise AirflowException(
airflow.exceptions.AirflowException: Bash command failed. The command returned a non-zero exit code 127.
[2024-07-03T19:20:59.089+0000] {taskinstance.py:1206} INFO - Marking task as UP_FOR_RETRY. dag_id=first_dag, task_id=first_task, run_id=scheduled__2023-07-08T00:00:00+00:00, execution_date=20230708T000000, start_date=20240703T192058, end_date=20240703T192059
[2024-07-03T19:20:59.149+0000] {standard_task_runner.py:110} ERROR - Failed to execute job 167 for task first_task (Bash command failed. The command returned a non-zero exit code 127.; 967)
[2024-07-03T19:20:59.185+0000] {local_task_job_runner.py:240} INFO - Task exited with return code 1
[2024-07-03T19:20:59.208+0000] {taskinstance.py:3503} INFO - 0 downstream tasks scheduled from follow-on schedule check
[2024-07-03T19:20:59.211+0000] {local_task_job_runner.py:222} INFO - ::endgroup::
