[2024-07-03T19:18:10.933+0000] {local_task_job_runner.py:120} INFO - ::group::Pre task execution logs
[2024-07-03T19:18:10.960+0000] {taskinstance.py:2076} INFO - Dependencies all met for dep_context=non-requeueable deps ti=<TaskInstance: first_dag.first_task scheduled__2023-07-08T00:00:00+00:00 [queued]>
[2024-07-03T19:18:10.970+0000] {taskinstance.py:2076} INFO - Dependencies all met for dep_context=requeueable deps ti=<TaskInstance: first_dag.first_task scheduled__2023-07-08T00:00:00+00:00 [queued]>
[2024-07-03T19:18:10.971+0000] {taskinstance.py:2306} INFO - Starting attempt 2 of 6
[2024-07-03T19:18:10.988+0000] {taskinstance.py:2330} INFO - Executing <Task(BashOperator): first_task> on 2023-07-08 00:00:00+00:00
[2024-07-03T19:18:10.995+0000] {warnings.py:112} WARNING - /home/***/.local/lib/python3.12/site-packages/***/task/task_runner/standard_task_runner.py:61: DeprecationWarning: This process (pid=875) is multi-threaded, use of fork() may lead to deadlocks in the child.
  pid = os.fork()

[2024-07-03T19:18:10.996+0000] {standard_task_runner.py:63} INFO - Started process 885 to run task
[2024-07-03T19:18:10.996+0000] {standard_task_runner.py:90} INFO - Running: ['***', 'tasks', 'run', 'first_dag', 'first_task', 'scheduled__2023-07-08T00:00:00+00:00', '--job-id', '151', '--raw', '--subdir', 'DAGS_FOLDER/first_dag.py', '--cfg-path', '/tmp/tmp2ajahbfz']
[2024-07-03T19:18:10.998+0000] {standard_task_runner.py:91} INFO - Job 151: Subtask first_task
[2024-07-03T19:18:11.057+0000] {task_command.py:426} INFO - Running <TaskInstance: first_dag.first_task scheduled__2023-07-08T00:00:00+00:00 [running]> on host 2a6e93921527
[2024-07-03T19:18:11.140+0000] {taskinstance.py:2648} INFO - Exporting env vars: AIRFLOW_CTX_DAG_OWNER='me' AIRFLOW_CTX_DAG_ID='first_dag' AIRFLOW_CTX_TASK_ID='first_task' AIRFLOW_CTX_EXECUTION_DATE='2023-07-08T00:00:00+00:00' AIRFLOW_CTX_TRY_NUMBER='2' AIRFLOW_CTX_DAG_RUN_ID='scheduled__2023-07-08T00:00:00+00:00'
[2024-07-03T19:18:11.141+0000] {taskinstance.py:430} INFO - ::endgroup::
[2024-07-03T19:18:11.156+0000] {subprocess.py:63} INFO - Tmp dir root location: /tmp
[2024-07-03T19:18:11.157+0000] {subprocess.py:75} INFO - Running command: ['/usr/bin/bash', '-c', 'Hello world, this is the first task']
[2024-07-03T19:18:11.171+0000] {subprocess.py:86} INFO - Output:
[2024-07-03T19:18:11.173+0000] {subprocess.py:93} INFO - /usr/bin/bash: line 1: Hello: command not found
[2024-07-03T19:18:11.174+0000] {subprocess.py:97} INFO - Command exited with return code 127
[2024-07-03T19:18:11.175+0000] {taskinstance.py:441} INFO - ::group::Post task execution logs
[2024-07-03T19:18:11.187+0000] {taskinstance.py:2905} ERROR - Task failed with exception
Traceback (most recent call last):
  File "/home/airflow/.local/lib/python3.12/site-packages/airflow/models/taskinstance.py", line 465, in _execute_task
    result = _execute_callable(context=context, **execute_callable_kwargs)
             ^^^^^^^^^^^^^^^^^^^^^^^^^^^^^^^^^^^^^^^^^^^^^^^^^^^^^^^^^^^^^
  File "/home/airflow/.local/lib/python3.12/site-packages/airflow/models/taskinstance.py", line 432, in _execute_callable
    return execute_callable(context=context, **execute_callable_kwargs)
           ^^^^^^^^^^^^^^^^^^^^^^^^^^^^^^^^^^^^^^^^^^^^^^^^^^^^^^^^^^^^
  File "/home/airflow/.local/lib/python3.12/site-packages/airflow/models/baseoperator.py", line 401, in wrapper
    return func(self, *args, **kwargs)
           ^^^^^^^^^^^^^^^^^^^^^^^^^^^
  File "/home/airflow/.local/lib/python3.12/site-packages/airflow/operators/bash.py", line 243, in execute
    raise AirflowException(
airflow.exceptions.AirflowException: Bash command failed. The command returned a non-zero exit code 127.
[2024-07-03T19:18:11.191+0000] {taskinstance.py:1206} INFO - Marking task as UP_FOR_RETRY. dag_id=first_dag, task_id=first_task, run_id=scheduled__2023-07-08T00:00:00+00:00, execution_date=20230708T000000, start_date=20240703T191810, end_date=20240703T191811
[2024-07-03T19:18:11.205+0000] {standard_task_runner.py:110} ERROR - Failed to execute job 151 for task first_task (Bash command failed. The command returned a non-zero exit code 127.; 885)
[2024-07-03T19:18:11.251+0000] {local_task_job_runner.py:240} INFO - Task exited with return code 1
[2024-07-03T19:18:11.269+0000] {taskinstance.py:3503} INFO - 0 downstream tasks scheduled from follow-on schedule check
[2024-07-03T19:18:11.272+0000] {local_task_job_runner.py:222} INFO - ::endgroup::
[2024-07-03T19:23:00.145+0000] {local_task_job_runner.py:120} INFO - ::group::Pre task execution logs
[2024-07-03T19:23:00.192+0000] {taskinstance.py:2076} INFO - Dependencies all met for dep_context=non-requeueable deps ti=<TaskInstance: first_dag.first_task scheduled__2023-07-08T00:00:00+00:00 [queued]>
[2024-07-03T19:23:00.206+0000] {taskinstance.py:2076} INFO - Dependencies all met for dep_context=requeueable deps ti=<TaskInstance: first_dag.first_task scheduled__2023-07-08T00:00:00+00:00 [queued]>
[2024-07-03T19:23:00.207+0000] {taskinstance.py:2306} INFO - Starting attempt 2 of 6
[2024-07-03T19:23:00.226+0000] {taskinstance.py:2330} INFO - Executing <Task(BashOperator): first_task> on 2023-07-08 00:00:00+00:00
[2024-07-03T19:23:00.238+0000] {warnings.py:112} WARNING - /home/***/.local/lib/python3.12/site-packages/***/task/task_runner/standard_task_runner.py:61: DeprecationWarning: This process (pid=1027) is multi-threaded, use of fork() may lead to deadlocks in the child.
  pid = os.fork()

[2024-07-03T19:23:00.239+0000] {standard_task_runner.py:63} INFO - Started process 1036 to run task
[2024-07-03T19:23:00.249+0000] {standard_task_runner.py:90} INFO - Running: ['***', 'tasks', 'run', 'first_dag', 'first_task', 'scheduled__2023-07-08T00:00:00+00:00', '--job-id', '178', '--raw', '--subdir', 'DAGS_FOLDER/first_dag.py', '--cfg-path', '/tmp/tmpx2rz3hpl']
[2024-07-03T19:23:00.250+0000] {standard_task_runner.py:91} INFO - Job 178: Subtask first_task
[2024-07-03T19:23:00.351+0000] {task_command.py:426} INFO - Running <TaskInstance: first_dag.first_task scheduled__2023-07-08T00:00:00+00:00 [running]> on host 2a6e93921527
[2024-07-03T19:23:00.479+0000] {taskinstance.py:2648} INFO - Exporting env vars: AIRFLOW_CTX_DAG_OWNER='me' AIRFLOW_CTX_DAG_ID='first_dag' AIRFLOW_CTX_TASK_ID='first_task' AIRFLOW_CTX_EXECUTION_DATE='2023-07-08T00:00:00+00:00' AIRFLOW_CTX_TRY_NUMBER='2' AIRFLOW_CTX_DAG_RUN_ID='scheduled__2023-07-08T00:00:00+00:00'
[2024-07-03T19:23:00.482+0000] {taskinstance.py:430} INFO - ::endgroup::
[2024-07-03T19:23:00.505+0000] {subprocess.py:63} INFO - Tmp dir root location: /tmp
[2024-07-03T19:23:00.506+0000] {subprocess.py:75} INFO - Running command: ['/usr/bin/bash', '-c', 'Hello world, this is the first task']
[2024-07-03T19:23:00.543+0000] {subprocess.py:86} INFO - Output:
[2024-07-03T19:23:00.547+0000] {subprocess.py:93} INFO - /usr/bin/bash: line 1: Hello: command not found
[2024-07-03T19:23:00.549+0000] {subprocess.py:97} INFO - Command exited with return code 127
[2024-07-03T19:23:00.550+0000] {taskinstance.py:441} INFO - ::group::Post task execution logs
[2024-07-03T19:23:00.582+0000] {taskinstance.py:2905} ERROR - Task failed with exception
Traceback (most recent call last):
  File "/home/airflow/.local/lib/python3.12/site-packages/airflow/models/taskinstance.py", line 465, in _execute_task
    result = _execute_callable(context=context, **execute_callable_kwargs)
             ^^^^^^^^^^^^^^^^^^^^^^^^^^^^^^^^^^^^^^^^^^^^^^^^^^^^^^^^^^^^^
  File "/home/airflow/.local/lib/python3.12/site-packages/airflow/models/taskinstance.py", line 432, in _execute_callable
    return execute_callable(context=context, **execute_callable_kwargs)
           ^^^^^^^^^^^^^^^^^^^^^^^^^^^^^^^^^^^^^^^^^^^^^^^^^^^^^^^^^^^^
  File "/home/airflow/.local/lib/python3.12/site-packages/airflow/models/baseoperator.py", line 401, in wrapper
    return func(self, *args, **kwargs)
           ^^^^^^^^^^^^^^^^^^^^^^^^^^^
  File "/home/airflow/.local/lib/python3.12/site-packages/airflow/operators/bash.py", line 243, in execute
    raise AirflowException(
airflow.exceptions.AirflowException: Bash command failed. The command returned a non-zero exit code 127.
[2024-07-03T19:23:00.590+0000] {taskinstance.py:1206} INFO - Marking task as UP_FOR_RETRY. dag_id=first_dag, task_id=first_task, run_id=scheduled__2023-07-08T00:00:00+00:00, execution_date=20230708T000000, start_date=20240703T192300, end_date=20240703T192300
[2024-07-03T19:23:00.645+0000] {standard_task_runner.py:110} ERROR - Failed to execute job 178 for task first_task (Bash command failed. The command returned a non-zero exit code 127.; 1036)
[2024-07-03T19:23:00.703+0000] {local_task_job_runner.py:240} INFO - Task exited with return code 1
[2024-07-03T19:23:00.719+0000] {local_task_job_runner.py:222} INFO - ::endgroup::
