[2024-07-03T19:18:12.023+0000] {local_task_job_runner.py:120} INFO - ::group::Pre task execution logs
[2024-07-03T19:18:12.046+0000] {taskinstance.py:2076} INFO - Dependencies all met for dep_context=non-requeueable deps ti=<TaskInstance: first_dag.first_task scheduled__2023-07-16T00:00:00+00:00 [queued]>
[2024-07-03T19:18:12.054+0000] {taskinstance.py:2076} INFO - Dependencies all met for dep_context=requeueable deps ti=<TaskInstance: first_dag.first_task scheduled__2023-07-16T00:00:00+00:00 [queued]>
[2024-07-03T19:18:12.054+0000] {taskinstance.py:2306} INFO - Starting attempt 2 of 6
[2024-07-03T19:18:12.068+0000] {taskinstance.py:2330} INFO - Executing <Task(BashOperator): first_task> on 2023-07-16 00:00:00+00:00
[2024-07-03T19:18:12.074+0000] {warnings.py:112} WARNING - /home/***/.local/lib/python3.12/site-packages/***/task/task_runner/standard_task_runner.py:61: DeprecationWarning: This process (pid=898) is multi-threaded, use of fork() may lead to deadlocks in the child.
  pid = os.fork()

[2024-07-03T19:18:12.075+0000] {standard_task_runner.py:63} INFO - Started process 905 to run task
[2024-07-03T19:18:12.075+0000] {standard_task_runner.py:90} INFO - Running: ['***', 'tasks', 'run', 'first_dag', 'first_task', 'scheduled__2023-07-16T00:00:00+00:00', '--job-id', '159', '--raw', '--subdir', 'DAGS_FOLDER/first_dag.py', '--cfg-path', '/tmp/tmpabprunmi']
[2024-07-03T19:18:12.076+0000] {standard_task_runner.py:91} INFO - Job 159: Subtask first_task
[2024-07-03T19:18:12.122+0000] {task_command.py:426} INFO - Running <TaskInstance: first_dag.first_task scheduled__2023-07-16T00:00:00+00:00 [running]> on host 2a6e93921527
[2024-07-03T19:18:12.198+0000] {taskinstance.py:2648} INFO - Exporting env vars: AIRFLOW_CTX_DAG_OWNER='me' AIRFLOW_CTX_DAG_ID='first_dag' AIRFLOW_CTX_TASK_ID='first_task' AIRFLOW_CTX_EXECUTION_DATE='2023-07-16T00:00:00+00:00' AIRFLOW_CTX_TRY_NUMBER='2' AIRFLOW_CTX_DAG_RUN_ID='scheduled__2023-07-16T00:00:00+00:00'
[2024-07-03T19:18:12.199+0000] {taskinstance.py:430} INFO - ::endgroup::
[2024-07-03T19:18:12.211+0000] {subprocess.py:63} INFO - Tmp dir root location: /tmp
[2024-07-03T19:18:12.212+0000] {subprocess.py:75} INFO - Running command: ['/usr/bin/bash', '-c', 'Hello world, this is the first task']
[2024-07-03T19:18:12.223+0000] {subprocess.py:86} INFO - Output:
[2024-07-03T19:18:12.224+0000] {subprocess.py:93} INFO - /usr/bin/bash: line 1: Hello: command not found
[2024-07-03T19:18:12.225+0000] {subprocess.py:97} INFO - Command exited with return code 127
[2024-07-03T19:18:12.226+0000] {taskinstance.py:441} INFO - ::group::Post task execution logs
[2024-07-03T19:18:12.234+0000] {taskinstance.py:2905} ERROR - Task failed with exception
Traceback (most recent call last):
  File "/home/airflow/.local/lib/python3.12/site-packages/airflow/models/taskinstance.py", line 465, in _execute_task
    result = _execute_callable(context=context, **execute_callable_kwargs)
             ^^^^^^^^^^^^^^^^^^^^^^^^^^^^^^^^^^^^^^^^^^^^^^^^^^^^^^^^^^^^^
  File "/home/airflow/.local/lib/python3.12/site-packages/airflow/models/taskinstance.py", line 432, in _execute_callable
    return execute_callable(context=context, **execute_callable_kwargs)
           ^^^^^^^^^^^^^^^^^^^^^^^^^^^^^^^^^^^^^^^^^^^^^^^^^^^^^^^^^^^^
  File "/home/airflow/.local/lib/python3.12/site-packages/airflow/models/baseoperator.py", line 401, in wrapper
    return func(self, *args, **kwargs)
           ^^^^^^^^^^^^^^^^^^^^^^^^^^^
  File "/home/airflow/.local/lib/python3.12/site-packages/airflow/operators/bash.py", line 243, in execute
    raise AirflowException(
airflow.exceptions.AirflowException: Bash command failed. The command returned a non-zero exit code 127.
[2024-07-03T19:18:12.241+0000] {taskinstance.py:1206} INFO - Marking task as UP_FOR_RETRY. dag_id=first_dag, task_id=first_task, run_id=scheduled__2023-07-16T00:00:00+00:00, execution_date=20230716T000000, start_date=20240703T191812, end_date=20240703T191812
[2024-07-03T19:18:12.255+0000] {standard_task_runner.py:110} ERROR - Failed to execute job 159 for task first_task (Bash command failed. The command returned a non-zero exit code 127.; 905)
[2024-07-03T19:18:12.289+0000] {local_task_job_runner.py:240} INFO - Task exited with return code 1
[2024-07-03T19:18:12.308+0000] {taskinstance.py:3503} INFO - 0 downstream tasks scheduled from follow-on schedule check
[2024-07-03T19:18:12.310+0000] {local_task_job_runner.py:222} INFO - ::endgroup::
[2024-07-03T19:23:01.462+0000] {local_task_job_runner.py:120} INFO - ::group::Pre task execution logs
[2024-07-03T19:23:01.495+0000] {taskinstance.py:2076} INFO - Dependencies all met for dep_context=non-requeueable deps ti=<TaskInstance: first_dag.first_task scheduled__2023-07-16T00:00:00+00:00 [queued]>
[2024-07-03T19:23:01.505+0000] {taskinstance.py:2076} INFO - Dependencies all met for dep_context=requeueable deps ti=<TaskInstance: first_dag.first_task scheduled__2023-07-16T00:00:00+00:00 [queued]>
[2024-07-03T19:23:01.506+0000] {taskinstance.py:2306} INFO - Starting attempt 2 of 6
[2024-07-03T19:23:01.523+0000] {taskinstance.py:2330} INFO - Executing <Task(BashOperator): first_task> on 2023-07-16 00:00:00+00:00
[2024-07-03T19:23:01.532+0000] {warnings.py:112} WARNING - /home/***/.local/lib/python3.12/site-packages/***/task/task_runner/standard_task_runner.py:61: DeprecationWarning: This process (pid=1054) is multi-threaded, use of fork() may lead to deadlocks in the child.
  pid = os.fork()

[2024-07-03T19:23:01.534+0000] {standard_task_runner.py:63} INFO - Started process 1065 to run task
[2024-07-03T19:23:01.534+0000] {standard_task_runner.py:90} INFO - Running: ['***', 'tasks', 'run', 'first_dag', 'first_task', 'scheduled__2023-07-16T00:00:00+00:00', '--job-id', '191', '--raw', '--subdir', 'DAGS_FOLDER/first_dag.py', '--cfg-path', '/tmp/tmpbjl98hoi']
[2024-07-03T19:23:01.536+0000] {standard_task_runner.py:91} INFO - Job 191: Subtask first_task
[2024-07-03T19:23:01.591+0000] {task_command.py:426} INFO - Running <TaskInstance: first_dag.first_task scheduled__2023-07-16T00:00:00+00:00 [running]> on host 2a6e93921527
[2024-07-03T19:23:01.684+0000] {taskinstance.py:2648} INFO - Exporting env vars: AIRFLOW_CTX_DAG_OWNER='me' AIRFLOW_CTX_DAG_ID='first_dag' AIRFLOW_CTX_TASK_ID='first_task' AIRFLOW_CTX_EXECUTION_DATE='2023-07-16T00:00:00+00:00' AIRFLOW_CTX_TRY_NUMBER='2' AIRFLOW_CTX_DAG_RUN_ID='scheduled__2023-07-16T00:00:00+00:00'
[2024-07-03T19:23:01.685+0000] {taskinstance.py:430} INFO - ::endgroup::
[2024-07-03T19:23:01.701+0000] {subprocess.py:63} INFO - Tmp dir root location: /tmp
[2024-07-03T19:23:01.702+0000] {subprocess.py:75} INFO - Running command: ['/usr/bin/bash', '-c', 'Hello world, this is the first task']
[2024-07-03T19:23:01.715+0000] {subprocess.py:86} INFO - Output:
[2024-07-03T19:23:01.716+0000] {subprocess.py:93} INFO - /usr/bin/bash: line 1: Hello: command not found
[2024-07-03T19:23:01.717+0000] {subprocess.py:97} INFO - Command exited with return code 127
[2024-07-03T19:23:01.717+0000] {taskinstance.py:441} INFO - ::group::Post task execution logs
[2024-07-03T19:23:01.729+0000] {taskinstance.py:2905} ERROR - Task failed with exception
Traceback (most recent call last):
  File "/home/airflow/.local/lib/python3.12/site-packages/airflow/models/taskinstance.py", line 465, in _execute_task
    result = _execute_callable(context=context, **execute_callable_kwargs)
             ^^^^^^^^^^^^^^^^^^^^^^^^^^^^^^^^^^^^^^^^^^^^^^^^^^^^^^^^^^^^^
  File "/home/airflow/.local/lib/python3.12/site-packages/airflow/models/taskinstance.py", line 432, in _execute_callable
    return execute_callable(context=context, **execute_callable_kwargs)
           ^^^^^^^^^^^^^^^^^^^^^^^^^^^^^^^^^^^^^^^^^^^^^^^^^^^^^^^^^^^^
  File "/home/airflow/.local/lib/python3.12/site-packages/airflow/models/baseoperator.py", line 401, in wrapper
    return func(self, *args, **kwargs)
           ^^^^^^^^^^^^^^^^^^^^^^^^^^^
  File "/home/airflow/.local/lib/python3.12/site-packages/airflow/operators/bash.py", line 243, in execute
    raise AirflowException(
airflow.exceptions.AirflowException: Bash command failed. The command returned a non-zero exit code 127.
[2024-07-03T19:23:01.733+0000] {taskinstance.py:1206} INFO - Marking task as UP_FOR_RETRY. dag_id=first_dag, task_id=first_task, run_id=scheduled__2023-07-16T00:00:00+00:00, execution_date=20230716T000000, start_date=20240703T192301, end_date=20240703T192301
[2024-07-03T19:23:01.746+0000] {standard_task_runner.py:110} ERROR - Failed to execute job 191 for task first_task (Bash command failed. The command returned a non-zero exit code 127.; 1065)
[2024-07-03T19:23:01.789+0000] {local_task_job_runner.py:240} INFO - Task exited with return code 1
[2024-07-03T19:23:01.811+0000] {taskinstance.py:3503} INFO - 0 downstream tasks scheduled from follow-on schedule check
[2024-07-03T19:23:01.814+0000] {local_task_job_runner.py:222} INFO - ::endgroup::
