[2024-07-03T19:18:10.203+0000] {local_task_job_runner.py:120} INFO - ::group::Pre task execution logs
[2024-07-03T19:18:10.226+0000] {taskinstance.py:2076} INFO - Dependencies all met for dep_context=non-requeueable deps ti=<TaskInstance: first_dag.first_task scheduled__2023-07-03T00:00:00+00:00 [queued]>
[2024-07-03T19:18:10.234+0000] {taskinstance.py:2076} INFO - Dependencies all met for dep_context=requeueable deps ti=<TaskInstance: first_dag.first_task scheduled__2023-07-03T00:00:00+00:00 [queued]>
[2024-07-03T19:18:10.235+0000] {taskinstance.py:2306} INFO - Starting attempt 2 of 6
[2024-07-03T19:18:10.251+0000] {taskinstance.py:2330} INFO - Executing <Task(BashOperator): first_task> on 2023-07-03 00:00:00+00:00
[2024-07-03T19:18:10.257+0000] {warnings.py:112} WARNING - /home/***/.local/lib/python3.12/site-packages/***/task/task_runner/standard_task_runner.py:61: DeprecationWarning: This process (pid=866) is multi-threaded, use of fork() may lead to deadlocks in the child.
  pid = os.fork()

[2024-07-03T19:18:10.259+0000] {standard_task_runner.py:63} INFO - Started process 871 to run task
[2024-07-03T19:18:10.258+0000] {standard_task_runner.py:90} INFO - Running: ['***', 'tasks', 'run', 'first_dag', 'first_task', 'scheduled__2023-07-03T00:00:00+00:00', '--job-id', '146', '--raw', '--subdir', 'DAGS_FOLDER/first_dag.py', '--cfg-path', '/tmp/tmp61psu6we']
[2024-07-03T19:18:10.260+0000] {standard_task_runner.py:91} INFO - Job 146: Subtask first_task
[2024-07-03T19:18:10.318+0000] {task_command.py:426} INFO - Running <TaskInstance: first_dag.first_task scheduled__2023-07-03T00:00:00+00:00 [running]> on host 2a6e93921527
[2024-07-03T19:18:10.417+0000] {taskinstance.py:2648} INFO - Exporting env vars: AIRFLOW_CTX_DAG_OWNER='me' AIRFLOW_CTX_DAG_ID='first_dag' AIRFLOW_CTX_TASK_ID='first_task' AIRFLOW_CTX_EXECUTION_DATE='2023-07-03T00:00:00+00:00' AIRFLOW_CTX_TRY_NUMBER='2' AIRFLOW_CTX_DAG_RUN_ID='scheduled__2023-07-03T00:00:00+00:00'
[2024-07-03T19:18:10.418+0000] {taskinstance.py:430} INFO - ::endgroup::
[2024-07-03T19:18:10.432+0000] {subprocess.py:63} INFO - Tmp dir root location: /tmp
[2024-07-03T19:18:10.433+0000] {subprocess.py:75} INFO - Running command: ['/usr/bin/bash', '-c', 'Hello world, this is the first task']
[2024-07-03T19:18:10.446+0000] {subprocess.py:86} INFO - Output:
[2024-07-03T19:18:10.448+0000] {subprocess.py:93} INFO - /usr/bin/bash: line 1: Hello: command not found
[2024-07-03T19:18:10.448+0000] {subprocess.py:97} INFO - Command exited with return code 127
[2024-07-03T19:18:10.449+0000] {taskinstance.py:441} INFO - ::group::Post task execution logs
[2024-07-03T19:18:10.459+0000] {taskinstance.py:2905} ERROR - Task failed with exception
Traceback (most recent call last):
  File "/home/airflow/.local/lib/python3.12/site-packages/airflow/models/taskinstance.py", line 465, in _execute_task
    result = _execute_callable(context=context, **execute_callable_kwargs)
             ^^^^^^^^^^^^^^^^^^^^^^^^^^^^^^^^^^^^^^^^^^^^^^^^^^^^^^^^^^^^^
  File "/home/airflow/.local/lib/python3.12/site-packages/airflow/models/taskinstance.py", line 432, in _execute_callable
    return execute_callable(context=context, **execute_callable_kwargs)
           ^^^^^^^^^^^^^^^^^^^^^^^^^^^^^^^^^^^^^^^^^^^^^^^^^^^^^^^^^^^^
  File "/home/airflow/.local/lib/python3.12/site-packages/airflow/models/baseoperator.py", line 401, in wrapper
    return func(self, *args, **kwargs)
           ^^^^^^^^^^^^^^^^^^^^^^^^^^^
  File "/home/airflow/.local/lib/python3.12/site-packages/airflow/operators/bash.py", line 243, in execute
    raise AirflowException(
airflow.exceptions.AirflowException: Bash command failed. The command returned a non-zero exit code 127.
[2024-07-03T19:18:10.463+0000] {taskinstance.py:1206} INFO - Marking task as UP_FOR_RETRY. dag_id=first_dag, task_id=first_task, run_id=scheduled__2023-07-03T00:00:00+00:00, execution_date=20230703T000000, start_date=20240703T191810, end_date=20240703T191810
[2024-07-03T19:18:10.479+0000] {standard_task_runner.py:110} ERROR - Failed to execute job 146 for task first_task (Bash command failed. The command returned a non-zero exit code 127.; 871)
[2024-07-03T19:18:10.513+0000] {local_task_job_runner.py:240} INFO - Task exited with return code 1
[2024-07-03T19:18:10.535+0000] {taskinstance.py:3503} INFO - 0 downstream tasks scheduled from follow-on schedule check
[2024-07-03T19:18:10.537+0000] {local_task_job_runner.py:222} INFO - ::endgroup::
[2024-07-03T19:23:00.163+0000] {local_task_job_runner.py:120} INFO - ::group::Pre task execution logs
[2024-07-03T19:23:00.209+0000] {taskinstance.py:2076} INFO - Dependencies all met for dep_context=non-requeueable deps ti=<TaskInstance: first_dag.first_task scheduled__2023-07-03T00:00:00+00:00 [queued]>
[2024-07-03T19:23:00.220+0000] {taskinstance.py:2076} INFO - Dependencies all met for dep_context=requeueable deps ti=<TaskInstance: first_dag.first_task scheduled__2023-07-03T00:00:00+00:00 [queued]>
[2024-07-03T19:23:00.221+0000] {taskinstance.py:2306} INFO - Starting attempt 2 of 6
[2024-07-03T19:23:00.249+0000] {taskinstance.py:2330} INFO - Executing <Task(BashOperator): first_task> on 2023-07-03 00:00:00+00:00
[2024-07-03T19:23:00.260+0000] {warnings.py:112} WARNING - /home/***/.local/lib/python3.12/site-packages/***/task/task_runner/standard_task_runner.py:61: DeprecationWarning: This process (pid=1029) is multi-threaded, use of fork() may lead to deadlocks in the child.
  pid = os.fork()

[2024-07-03T19:23:00.265+0000] {standard_task_runner.py:90} INFO - Running: ['***', 'tasks', 'run', 'first_dag', 'first_task', 'scheduled__2023-07-03T00:00:00+00:00', '--job-id', '183', '--raw', '--subdir', 'DAGS_FOLDER/first_dag.py', '--cfg-path', '/tmp/tmpk4apj0lc']
[2024-07-03T19:23:00.268+0000] {standard_task_runner.py:91} INFO - Job 183: Subtask first_task
[2024-07-03T19:23:00.267+0000] {standard_task_runner.py:63} INFO - Started process 1040 to run task
[2024-07-03T19:23:00.367+0000] {task_command.py:426} INFO - Running <TaskInstance: first_dag.first_task scheduled__2023-07-03T00:00:00+00:00 [running]> on host 2a6e93921527
[2024-07-03T19:23:00.513+0000] {taskinstance.py:2648} INFO - Exporting env vars: AIRFLOW_CTX_DAG_OWNER='me' AIRFLOW_CTX_DAG_ID='first_dag' AIRFLOW_CTX_TASK_ID='first_task' AIRFLOW_CTX_EXECUTION_DATE='2023-07-03T00:00:00+00:00' AIRFLOW_CTX_TRY_NUMBER='2' AIRFLOW_CTX_DAG_RUN_ID='scheduled__2023-07-03T00:00:00+00:00'
[2024-07-03T19:23:00.518+0000] {taskinstance.py:430} INFO - ::endgroup::
[2024-07-03T19:23:00.535+0000] {subprocess.py:63} INFO - Tmp dir root location: /tmp
[2024-07-03T19:23:00.537+0000] {subprocess.py:75} INFO - Running command: ['/usr/bin/bash', '-c', 'Hello world, this is the first task']
[2024-07-03T19:23:00.562+0000] {subprocess.py:86} INFO - Output:
[2024-07-03T19:23:00.564+0000] {subprocess.py:93} INFO - /usr/bin/bash: line 1: Hello: command not found
[2024-07-03T19:23:00.569+0000] {subprocess.py:97} INFO - Command exited with return code 127
[2024-07-03T19:23:00.570+0000] {taskinstance.py:441} INFO - ::group::Post task execution logs
[2024-07-03T19:23:00.588+0000] {taskinstance.py:2905} ERROR - Task failed with exception
Traceback (most recent call last):
  File "/home/airflow/.local/lib/python3.12/site-packages/airflow/models/taskinstance.py", line 465, in _execute_task
    result = _execute_callable(context=context, **execute_callable_kwargs)
             ^^^^^^^^^^^^^^^^^^^^^^^^^^^^^^^^^^^^^^^^^^^^^^^^^^^^^^^^^^^^^
  File "/home/airflow/.local/lib/python3.12/site-packages/airflow/models/taskinstance.py", line 432, in _execute_callable
    return execute_callable(context=context, **execute_callable_kwargs)
           ^^^^^^^^^^^^^^^^^^^^^^^^^^^^^^^^^^^^^^^^^^^^^^^^^^^^^^^^^^^^
  File "/home/airflow/.local/lib/python3.12/site-packages/airflow/models/baseoperator.py", line 401, in wrapper
    return func(self, *args, **kwargs)
           ^^^^^^^^^^^^^^^^^^^^^^^^^^^
  File "/home/airflow/.local/lib/python3.12/site-packages/airflow/operators/bash.py", line 243, in execute
    raise AirflowException(
airflow.exceptions.AirflowException: Bash command failed. The command returned a non-zero exit code 127.
[2024-07-03T19:23:00.595+0000] {taskinstance.py:1206} INFO - Marking task as UP_FOR_RETRY. dag_id=first_dag, task_id=first_task, run_id=scheduled__2023-07-03T00:00:00+00:00, execution_date=20230703T000000, start_date=20240703T192300, end_date=20240703T192300
[2024-07-03T19:23:00.644+0000] {standard_task_runner.py:110} ERROR - Failed to execute job 183 for task first_task (Bash command failed. The command returned a non-zero exit code 127.; 1040)
[2024-07-03T19:23:00.692+0000] {local_task_job_runner.py:240} INFO - Task exited with return code 1
[2024-07-03T19:23:00.706+0000] {local_task_job_runner.py:222} INFO - ::endgroup::
