[2024-07-03T19:16:10.433+0000] {local_task_job_runner.py:120} INFO - ::group::Pre task execution logs
[2024-07-03T19:16:10.458+0000] {taskinstance.py:2076} INFO - Dependencies all met for dep_context=non-requeueable deps ti=<TaskInstance: first_dag.first_task scheduled__2023-07-11T00:00:00+00:00 [queued]>
[2024-07-03T19:16:10.466+0000] {taskinstance.py:2076} INFO - Dependencies all met for dep_context=requeueable deps ti=<TaskInstance: first_dag.first_task scheduled__2023-07-11T00:00:00+00:00 [queued]>
[2024-07-03T19:16:10.467+0000] {taskinstance.py:2306} INFO - Starting attempt 1 of 6
[2024-07-03T19:16:10.506+0000] {taskinstance.py:2330} INFO - Executing <Task(BashOperator): first_task> on 2023-07-11 00:00:00+00:00
[2024-07-03T19:16:10.513+0000] {warnings.py:112} WARNING - /home/***/.local/lib/python3.12/site-packages/***/task/task_runner/standard_task_runner.py:61: DeprecationWarning: This process (pid=806) is multi-threaded, use of fork() may lead to deadlocks in the child.
  pid = os.fork()

[2024-07-03T19:16:10.515+0000] {standard_task_runner.py:63} INFO - Started process 816 to run task
[2024-07-03T19:16:10.514+0000] {standard_task_runner.py:90} INFO - Running: ['***', 'tasks', 'run', 'first_dag', 'first_task', 'scheduled__2023-07-11T00:00:00+00:00', '--job-id', '138', '--raw', '--subdir', 'DAGS_FOLDER/first_dag.py', '--cfg-path', '/tmp/tmpeo37xxok']
[2024-07-03T19:16:10.516+0000] {standard_task_runner.py:91} INFO - Job 138: Subtask first_task
[2024-07-03T19:16:10.568+0000] {task_command.py:426} INFO - Running <TaskInstance: first_dag.first_task scheduled__2023-07-11T00:00:00+00:00 [running]> on host 2a6e93921527
[2024-07-03T19:16:10.658+0000] {taskinstance.py:2648} INFO - Exporting env vars: AIRFLOW_CTX_DAG_OWNER='me' AIRFLOW_CTX_DAG_ID='first_dag' AIRFLOW_CTX_TASK_ID='first_task' AIRFLOW_CTX_EXECUTION_DATE='2023-07-11T00:00:00+00:00' AIRFLOW_CTX_TRY_NUMBER='1' AIRFLOW_CTX_DAG_RUN_ID='scheduled__2023-07-11T00:00:00+00:00'
[2024-07-03T19:16:10.659+0000] {taskinstance.py:430} INFO - ::endgroup::
[2024-07-03T19:16:10.672+0000] {subprocess.py:63} INFO - Tmp dir root location: /tmp
[2024-07-03T19:16:10.673+0000] {subprocess.py:75} INFO - Running command: ['/usr/bin/bash', '-c', 'Hello world, this is the first task']
[2024-07-03T19:16:10.685+0000] {subprocess.py:86} INFO - Output:
[2024-07-03T19:16:10.687+0000] {subprocess.py:93} INFO - /usr/bin/bash: line 1: Hello: command not found
[2024-07-03T19:16:10.687+0000] {subprocess.py:97} INFO - Command exited with return code 127
[2024-07-03T19:16:10.688+0000] {taskinstance.py:441} INFO - ::group::Post task execution logs
[2024-07-03T19:16:10.701+0000] {taskinstance.py:2905} ERROR - Task failed with exception
Traceback (most recent call last):
  File "/home/airflow/.local/lib/python3.12/site-packages/airflow/models/taskinstance.py", line 465, in _execute_task
    result = _execute_callable(context=context, **execute_callable_kwargs)
             ^^^^^^^^^^^^^^^^^^^^^^^^^^^^^^^^^^^^^^^^^^^^^^^^^^^^^^^^^^^^^
  File "/home/airflow/.local/lib/python3.12/site-packages/airflow/models/taskinstance.py", line 432, in _execute_callable
    return execute_callable(context=context, **execute_callable_kwargs)
           ^^^^^^^^^^^^^^^^^^^^^^^^^^^^^^^^^^^^^^^^^^^^^^^^^^^^^^^^^^^^
  File "/home/airflow/.local/lib/python3.12/site-packages/airflow/models/baseoperator.py", line 401, in wrapper
    return func(self, *args, **kwargs)
           ^^^^^^^^^^^^^^^^^^^^^^^^^^^
  File "/home/airflow/.local/lib/python3.12/site-packages/airflow/operators/bash.py", line 243, in execute
    raise AirflowException(
airflow.exceptions.AirflowException: Bash command failed. The command returned a non-zero exit code 127.
[2024-07-03T19:16:10.707+0000] {taskinstance.py:1206} INFO - Marking task as UP_FOR_RETRY. dag_id=first_dag, task_id=first_task, run_id=scheduled__2023-07-11T00:00:00+00:00, execution_date=20230711T000000, start_date=20240703T191610, end_date=20240703T191610
[2024-07-03T19:16:10.723+0000] {standard_task_runner.py:110} ERROR - Failed to execute job 138 for task first_task (Bash command failed. The command returned a non-zero exit code 127.; 816)
[2024-07-03T19:16:10.769+0000] {local_task_job_runner.py:240} INFO - Task exited with return code 1
[2024-07-03T19:16:10.778+0000] {local_task_job_runner.py:222} INFO - ::endgroup::
[2024-07-03T19:20:59.246+0000] {local_task_job_runner.py:120} INFO - ::group::Pre task execution logs
[2024-07-03T19:20:59.305+0000] {taskinstance.py:2076} INFO - Dependencies all met for dep_context=non-requeueable deps ti=<TaskInstance: first_dag.first_task scheduled__2023-07-11T00:00:00+00:00 [queued]>
[2024-07-03T19:20:59.319+0000] {taskinstance.py:2076} INFO - Dependencies all met for dep_context=requeueable deps ti=<TaskInstance: first_dag.first_task scheduled__2023-07-11T00:00:00+00:00 [queued]>
[2024-07-03T19:20:59.320+0000] {taskinstance.py:2306} INFO - Starting attempt 1 of 6
[2024-07-03T19:20:59.375+0000] {taskinstance.py:2330} INFO - Executing <Task(BashOperator): first_task> on 2023-07-11 00:00:00+00:00
[2024-07-03T19:20:59.389+0000] {warnings.py:112} WARNING - /home/***/.local/lib/python3.12/site-packages/***/task/task_runner/standard_task_runner.py:61: DeprecationWarning: This process (pid=965) is multi-threaded, use of fork() may lead to deadlocks in the child.
  pid = os.fork()

[2024-07-03T19:20:59.395+0000] {standard_task_runner.py:63} INFO - Started process 976 to run task
[2024-07-03T19:20:59.394+0000] {standard_task_runner.py:90} INFO - Running: ['***', 'tasks', 'run', 'first_dag', 'first_task', 'scheduled__2023-07-11T00:00:00+00:00', '--job-id', '170', '--raw', '--subdir', 'DAGS_FOLDER/first_dag.py', '--cfg-path', '/tmp/tmpsxjd2g5q']
[2024-07-03T19:20:59.398+0000] {standard_task_runner.py:91} INFO - Job 170: Subtask first_task
[2024-07-03T19:20:59.457+0000] {task_command.py:426} INFO - Running <TaskInstance: first_dag.first_task scheduled__2023-07-11T00:00:00+00:00 [running]> on host 2a6e93921527
[2024-07-03T19:20:59.575+0000] {taskinstance.py:2648} INFO - Exporting env vars: AIRFLOW_CTX_DAG_OWNER='me' AIRFLOW_CTX_DAG_ID='first_dag' AIRFLOW_CTX_TASK_ID='first_task' AIRFLOW_CTX_EXECUTION_DATE='2023-07-11T00:00:00+00:00' AIRFLOW_CTX_TRY_NUMBER='1' AIRFLOW_CTX_DAG_RUN_ID='scheduled__2023-07-11T00:00:00+00:00'
[2024-07-03T19:20:59.576+0000] {taskinstance.py:430} INFO - ::endgroup::
[2024-07-03T19:20:59.592+0000] {subprocess.py:63} INFO - Tmp dir root location: /tmp
[2024-07-03T19:20:59.593+0000] {subprocess.py:75} INFO - Running command: ['/usr/bin/bash', '-c', 'Hello world, this is the first task']
[2024-07-03T19:20:59.610+0000] {subprocess.py:86} INFO - Output:
[2024-07-03T19:20:59.612+0000] {subprocess.py:93} INFO - /usr/bin/bash: line 1: Hello: command not found
[2024-07-03T19:20:59.613+0000] {subprocess.py:97} INFO - Command exited with return code 127
[2024-07-03T19:20:59.615+0000] {taskinstance.py:441} INFO - ::group::Post task execution logs
[2024-07-03T19:20:59.631+0000] {taskinstance.py:2905} ERROR - Task failed with exception
Traceback (most recent call last):
  File "/home/airflow/.local/lib/python3.12/site-packages/airflow/models/taskinstance.py", line 465, in _execute_task
    result = _execute_callable(context=context, **execute_callable_kwargs)
             ^^^^^^^^^^^^^^^^^^^^^^^^^^^^^^^^^^^^^^^^^^^^^^^^^^^^^^^^^^^^^
  File "/home/airflow/.local/lib/python3.12/site-packages/airflow/models/taskinstance.py", line 432, in _execute_callable
    return execute_callable(context=context, **execute_callable_kwargs)
           ^^^^^^^^^^^^^^^^^^^^^^^^^^^^^^^^^^^^^^^^^^^^^^^^^^^^^^^^^^^^
  File "/home/airflow/.local/lib/python3.12/site-packages/airflow/models/baseoperator.py", line 401, in wrapper
    return func(self, *args, **kwargs)
           ^^^^^^^^^^^^^^^^^^^^^^^^^^^
  File "/home/airflow/.local/lib/python3.12/site-packages/airflow/operators/bash.py", line 243, in execute
    raise AirflowException(
airflow.exceptions.AirflowException: Bash command failed. The command returned a non-zero exit code 127.
[2024-07-03T19:20:59.639+0000] {taskinstance.py:1206} INFO - Marking task as UP_FOR_RETRY. dag_id=first_dag, task_id=first_task, run_id=scheduled__2023-07-11T00:00:00+00:00, execution_date=20230711T000000, start_date=20240703T192059, end_date=20240703T192059
[2024-07-03T19:20:59.662+0000] {standard_task_runner.py:110} ERROR - Failed to execute job 170 for task first_task (Bash command failed. The command returned a non-zero exit code 127.; 976)
[2024-07-03T19:20:59.692+0000] {local_task_job_runner.py:240} INFO - Task exited with return code 1
[2024-07-03T19:20:59.714+0000] {taskinstance.py:3503} INFO - 0 downstream tasks scheduled from follow-on schedule check
[2024-07-03T19:20:59.718+0000] {local_task_job_runner.py:222} INFO - ::endgroup::
