[2024-07-03T19:16:11.417+0000] {local_task_job_runner.py:120} INFO - ::group::Pre task execution logs
[2024-07-03T19:16:11.439+0000] {taskinstance.py:2076} INFO - Dependencies all met for dep_context=non-requeueable deps ti=<TaskInstance: first_dag.first_task scheduled__2023-07-17T00:00:00+00:00 [queued]>
[2024-07-03T19:16:11.446+0000] {taskinstance.py:2076} INFO - Dependencies all met for dep_context=requeueable deps ti=<TaskInstance: first_dag.first_task scheduled__2023-07-17T00:00:00+00:00 [queued]>
[2024-07-03T19:16:11.447+0000] {taskinstance.py:2306} INFO - Starting attempt 1 of 6
[2024-07-03T19:16:11.462+0000] {taskinstance.py:2330} INFO - Executing <Task(BashOperator): first_task> on 2023-07-17 00:00:00+00:00
[2024-07-03T19:16:11.468+0000] {warnings.py:112} WARNING - /home/***/.local/lib/python3.12/site-packages/***/task/task_runner/standard_task_runner.py:61: DeprecationWarning: This process (pid=826) is multi-threaded, use of fork() may lead to deadlocks in the child.
  pid = os.fork()

[2024-07-03T19:16:11.469+0000] {standard_task_runner.py:63} INFO - Started process 831 to run task
[2024-07-03T19:16:11.469+0000] {standard_task_runner.py:90} INFO - Running: ['***', 'tasks', 'run', 'first_dag', 'first_task', 'scheduled__2023-07-17T00:00:00+00:00', '--job-id', '144', '--raw', '--subdir', 'DAGS_FOLDER/first_dag.py', '--cfg-path', '/tmp/tmputmzoa_z']
[2024-07-03T19:16:11.470+0000] {standard_task_runner.py:91} INFO - Job 144: Subtask first_task
[2024-07-03T19:16:11.512+0000] {task_command.py:426} INFO - Running <TaskInstance: first_dag.first_task scheduled__2023-07-17T00:00:00+00:00 [running]> on host 2a6e93921527
[2024-07-03T19:16:11.592+0000] {taskinstance.py:2648} INFO - Exporting env vars: AIRFLOW_CTX_DAG_OWNER='me' AIRFLOW_CTX_DAG_ID='first_dag' AIRFLOW_CTX_TASK_ID='first_task' AIRFLOW_CTX_EXECUTION_DATE='2023-07-17T00:00:00+00:00' AIRFLOW_CTX_TRY_NUMBER='1' AIRFLOW_CTX_DAG_RUN_ID='scheduled__2023-07-17T00:00:00+00:00'
[2024-07-03T19:16:11.592+0000] {taskinstance.py:430} INFO - ::endgroup::
[2024-07-03T19:16:11.603+0000] {subprocess.py:63} INFO - Tmp dir root location: /tmp
[2024-07-03T19:16:11.604+0000] {subprocess.py:75} INFO - Running command: ['/usr/bin/bash', '-c', 'Hello world, this is the first task']
[2024-07-03T19:16:11.613+0000] {subprocess.py:86} INFO - Output:
[2024-07-03T19:16:11.615+0000] {subprocess.py:93} INFO - /usr/bin/bash: line 1: Hello: command not found
[2024-07-03T19:16:11.615+0000] {subprocess.py:97} INFO - Command exited with return code 127
[2024-07-03T19:16:11.616+0000] {taskinstance.py:441} INFO - ::group::Post task execution logs
[2024-07-03T19:16:11.625+0000] {taskinstance.py:2905} ERROR - Task failed with exception
Traceback (most recent call last):
  File "/home/airflow/.local/lib/python3.12/site-packages/airflow/models/taskinstance.py", line 465, in _execute_task
    result = _execute_callable(context=context, **execute_callable_kwargs)
             ^^^^^^^^^^^^^^^^^^^^^^^^^^^^^^^^^^^^^^^^^^^^^^^^^^^^^^^^^^^^^
  File "/home/airflow/.local/lib/python3.12/site-packages/airflow/models/taskinstance.py", line 432, in _execute_callable
    return execute_callable(context=context, **execute_callable_kwargs)
           ^^^^^^^^^^^^^^^^^^^^^^^^^^^^^^^^^^^^^^^^^^^^^^^^^^^^^^^^^^^^
  File "/home/airflow/.local/lib/python3.12/site-packages/airflow/models/baseoperator.py", line 401, in wrapper
    return func(self, *args, **kwargs)
           ^^^^^^^^^^^^^^^^^^^^^^^^^^^
  File "/home/airflow/.local/lib/python3.12/site-packages/airflow/operators/bash.py", line 243, in execute
    raise AirflowException(
airflow.exceptions.AirflowException: Bash command failed. The command returned a non-zero exit code 127.
[2024-07-03T19:16:11.629+0000] {taskinstance.py:1206} INFO - Marking task as UP_FOR_RETRY. dag_id=first_dag, task_id=first_task, run_id=scheduled__2023-07-17T00:00:00+00:00, execution_date=20230717T000000, start_date=20240703T191611, end_date=20240703T191611
[2024-07-03T19:16:11.639+0000] {standard_task_runner.py:110} ERROR - Failed to execute job 144 for task first_task (Bash command failed. The command returned a non-zero exit code 127.; 831)
[2024-07-03T19:16:11.683+0000] {local_task_job_runner.py:240} INFO - Task exited with return code 1
[2024-07-03T19:16:11.698+0000] {taskinstance.py:3503} INFO - 0 downstream tasks scheduled from follow-on schedule check
[2024-07-03T19:16:11.701+0000] {local_task_job_runner.py:222} INFO - ::endgroup::
[2024-07-03T19:21:00.463+0000] {local_task_job_runner.py:120} INFO - ::group::Pre task execution logs
[2024-07-03T19:21:00.490+0000] {taskinstance.py:2076} INFO - Dependencies all met for dep_context=non-requeueable deps ti=<TaskInstance: first_dag.first_task scheduled__2023-07-17T00:00:00+00:00 [queued]>
[2024-07-03T19:21:00.511+0000] {taskinstance.py:2076} INFO - Dependencies all met for dep_context=requeueable deps ti=<TaskInstance: first_dag.first_task scheduled__2023-07-17T00:00:00+00:00 [queued]>
[2024-07-03T19:21:00.512+0000] {taskinstance.py:2306} INFO - Starting attempt 1 of 6
[2024-07-03T19:21:00.530+0000] {taskinstance.py:2330} INFO - Executing <Task(BashOperator): first_task> on 2023-07-17 00:00:00+00:00
[2024-07-03T19:21:00.538+0000] {warnings.py:112} WARNING - /home/***/.local/lib/python3.12/site-packages/***/task/task_runner/standard_task_runner.py:61: DeprecationWarning: This process (pid=986) is multi-threaded, use of fork() may lead to deadlocks in the child.
  pid = os.fork()

[2024-07-03T19:21:00.539+0000] {standard_task_runner.py:63} INFO - Started process 992 to run task
[2024-07-03T19:21:00.540+0000] {standard_task_runner.py:90} INFO - Running: ['***', 'tasks', 'run', 'first_dag', 'first_task', 'scheduled__2023-07-17T00:00:00+00:00', '--job-id', '176', '--raw', '--subdir', 'DAGS_FOLDER/first_dag.py', '--cfg-path', '/tmp/tmplif5spev']
[2024-07-03T19:21:00.541+0000] {standard_task_runner.py:91} INFO - Job 176: Subtask first_task
[2024-07-03T19:21:00.589+0000] {task_command.py:426} INFO - Running <TaskInstance: first_dag.first_task scheduled__2023-07-17T00:00:00+00:00 [running]> on host 2a6e93921527
[2024-07-03T19:21:00.678+0000] {taskinstance.py:2648} INFO - Exporting env vars: AIRFLOW_CTX_DAG_OWNER='me' AIRFLOW_CTX_DAG_ID='first_dag' AIRFLOW_CTX_TASK_ID='first_task' AIRFLOW_CTX_EXECUTION_DATE='2023-07-17T00:00:00+00:00' AIRFLOW_CTX_TRY_NUMBER='1' AIRFLOW_CTX_DAG_RUN_ID='scheduled__2023-07-17T00:00:00+00:00'
[2024-07-03T19:21:00.679+0000] {taskinstance.py:430} INFO - ::endgroup::
[2024-07-03T19:21:00.691+0000] {subprocess.py:63} INFO - Tmp dir root location: /tmp
[2024-07-03T19:21:00.692+0000] {subprocess.py:75} INFO - Running command: ['/usr/bin/bash', '-c', 'Hello world, this is the first task']
[2024-07-03T19:21:00.705+0000] {subprocess.py:86} INFO - Output:
[2024-07-03T19:21:00.707+0000] {subprocess.py:93} INFO - /usr/bin/bash: line 1: Hello: command not found
[2024-07-03T19:21:00.708+0000] {subprocess.py:97} INFO - Command exited with return code 127
[2024-07-03T19:21:00.708+0000] {taskinstance.py:441} INFO - ::group::Post task execution logs
[2024-07-03T19:21:00.720+0000] {taskinstance.py:2905} ERROR - Task failed with exception
Traceback (most recent call last):
  File "/home/airflow/.local/lib/python3.12/site-packages/airflow/models/taskinstance.py", line 465, in _execute_task
    result = _execute_callable(context=context, **execute_callable_kwargs)
             ^^^^^^^^^^^^^^^^^^^^^^^^^^^^^^^^^^^^^^^^^^^^^^^^^^^^^^^^^^^^^
  File "/home/airflow/.local/lib/python3.12/site-packages/airflow/models/taskinstance.py", line 432, in _execute_callable
    return execute_callable(context=context, **execute_callable_kwargs)
           ^^^^^^^^^^^^^^^^^^^^^^^^^^^^^^^^^^^^^^^^^^^^^^^^^^^^^^^^^^^^
  File "/home/airflow/.local/lib/python3.12/site-packages/airflow/models/baseoperator.py", line 401, in wrapper
    return func(self, *args, **kwargs)
           ^^^^^^^^^^^^^^^^^^^^^^^^^^^
  File "/home/airflow/.local/lib/python3.12/site-packages/airflow/operators/bash.py", line 243, in execute
    raise AirflowException(
airflow.exceptions.AirflowException: Bash command failed. The command returned a non-zero exit code 127.
[2024-07-03T19:21:00.724+0000] {taskinstance.py:1206} INFO - Marking task as UP_FOR_RETRY. dag_id=first_dag, task_id=first_task, run_id=scheduled__2023-07-17T00:00:00+00:00, execution_date=20230717T000000, start_date=20240703T192100, end_date=20240703T192100
[2024-07-03T19:21:00.736+0000] {standard_task_runner.py:110} ERROR - Failed to execute job 176 for task first_task (Bash command failed. The command returned a non-zero exit code 127.; 992)
[2024-07-03T19:21:00.754+0000] {local_task_job_runner.py:240} INFO - Task exited with return code 1
[2024-07-03T19:21:00.770+0000] {taskinstance.py:3503} INFO - 0 downstream tasks scheduled from follow-on schedule check
[2024-07-03T19:21:00.772+0000] {local_task_job_runner.py:222} INFO - ::endgroup::
