[2024-07-03T19:16:10.250+0000] {local_task_job_runner.py:120} INFO - ::group::Pre task execution logs
[2024-07-03T19:16:10.274+0000] {taskinstance.py:2076} INFO - Dependencies all met for dep_context=non-requeueable deps ti=<TaskInstance: first_dag.first_task scheduled__2023-07-10T00:00:00+00:00 [queued]>
[2024-07-03T19:16:10.281+0000] {taskinstance.py:2076} INFO - Dependencies all met for dep_context=requeueable deps ti=<TaskInstance: first_dag.first_task scheduled__2023-07-10T00:00:00+00:00 [queued]>
[2024-07-03T19:16:10.282+0000] {taskinstance.py:2306} INFO - Starting attempt 1 of 6
[2024-07-03T19:16:10.298+0000] {taskinstance.py:2330} INFO - Executing <Task(BashOperator): first_task> on 2023-07-10 00:00:00+00:00
[2024-07-03T19:16:10.307+0000] {warnings.py:112} WARNING - /home/***/.local/lib/python3.12/site-packages/***/task/task_runner/standard_task_runner.py:61: DeprecationWarning: This process (pid=802) is multi-threaded, use of fork() may lead to deadlocks in the child.
  pid = os.fork()

[2024-07-03T19:16:10.308+0000] {standard_task_runner.py:63} INFO - Started process 812 to run task
[2024-07-03T19:16:10.308+0000] {standard_task_runner.py:90} INFO - Running: ['***', 'tasks', 'run', 'first_dag', 'first_task', 'scheduled__2023-07-10T00:00:00+00:00', '--job-id', '137', '--raw', '--subdir', 'DAGS_FOLDER/first_dag.py', '--cfg-path', '/tmp/tmpc_nnt3lr']
[2024-07-03T19:16:10.310+0000] {standard_task_runner.py:91} INFO - Job 137: Subtask first_task
[2024-07-03T19:16:10.387+0000] {task_command.py:426} INFO - Running <TaskInstance: first_dag.first_task scheduled__2023-07-10T00:00:00+00:00 [running]> on host 2a6e93921527
[2024-07-03T19:16:10.480+0000] {taskinstance.py:2648} INFO - Exporting env vars: AIRFLOW_CTX_DAG_OWNER='me' AIRFLOW_CTX_DAG_ID='first_dag' AIRFLOW_CTX_TASK_ID='first_task' AIRFLOW_CTX_EXECUTION_DATE='2023-07-10T00:00:00+00:00' AIRFLOW_CTX_TRY_NUMBER='1' AIRFLOW_CTX_DAG_RUN_ID='scheduled__2023-07-10T00:00:00+00:00'
[2024-07-03T19:16:10.481+0000] {taskinstance.py:430} INFO - ::endgroup::
[2024-07-03T19:16:10.493+0000] {subprocess.py:63} INFO - Tmp dir root location: /tmp
[2024-07-03T19:16:10.494+0000] {subprocess.py:75} INFO - Running command: ['/usr/bin/bash', '-c', 'Hello world, this is the first task']
[2024-07-03T19:16:10.506+0000] {subprocess.py:86} INFO - Output:
[2024-07-03T19:16:10.508+0000] {subprocess.py:93} INFO - /usr/bin/bash: line 1: Hello: command not found
[2024-07-03T19:16:10.508+0000] {subprocess.py:97} INFO - Command exited with return code 127
[2024-07-03T19:16:10.509+0000] {taskinstance.py:441} INFO - ::group::Post task execution logs
[2024-07-03T19:16:10.520+0000] {taskinstance.py:2905} ERROR - Task failed with exception
Traceback (most recent call last):
  File "/home/airflow/.local/lib/python3.12/site-packages/airflow/models/taskinstance.py", line 465, in _execute_task
    result = _execute_callable(context=context, **execute_callable_kwargs)
             ^^^^^^^^^^^^^^^^^^^^^^^^^^^^^^^^^^^^^^^^^^^^^^^^^^^^^^^^^^^^^
  File "/home/airflow/.local/lib/python3.12/site-packages/airflow/models/taskinstance.py", line 432, in _execute_callable
    return execute_callable(context=context, **execute_callable_kwargs)
           ^^^^^^^^^^^^^^^^^^^^^^^^^^^^^^^^^^^^^^^^^^^^^^^^^^^^^^^^^^^^
  File "/home/airflow/.local/lib/python3.12/site-packages/airflow/models/baseoperator.py", line 401, in wrapper
    return func(self, *args, **kwargs)
           ^^^^^^^^^^^^^^^^^^^^^^^^^^^
  File "/home/airflow/.local/lib/python3.12/site-packages/airflow/operators/bash.py", line 243, in execute
    raise AirflowException(
airflow.exceptions.AirflowException: Bash command failed. The command returned a non-zero exit code 127.
[2024-07-03T19:16:10.525+0000] {taskinstance.py:1206} INFO - Marking task as UP_FOR_RETRY. dag_id=first_dag, task_id=first_task, run_id=scheduled__2023-07-10T00:00:00+00:00, execution_date=20230710T000000, start_date=20240703T191610, end_date=20240703T191610
[2024-07-03T19:16:10.541+0000] {standard_task_runner.py:110} ERROR - Failed to execute job 137 for task first_task (Bash command failed. The command returned a non-zero exit code 127.; 812)
[2024-07-03T19:16:10.566+0000] {local_task_job_runner.py:240} INFO - Task exited with return code 1
[2024-07-03T19:16:10.584+0000] {taskinstance.py:3503} INFO - 0 downstream tasks scheduled from follow-on schedule check
[2024-07-03T19:16:10.586+0000] {local_task_job_runner.py:222} INFO - ::endgroup::
[2024-07-03T19:20:59.087+0000] {local_task_job_runner.py:120} INFO - ::group::Pre task execution logs
[2024-07-03T19:20:59.113+0000] {taskinstance.py:2076} INFO - Dependencies all met for dep_context=non-requeueable deps ti=<TaskInstance: first_dag.first_task scheduled__2023-07-10T00:00:00+00:00 [queued]>
[2024-07-03T19:20:59.122+0000] {taskinstance.py:2076} INFO - Dependencies all met for dep_context=requeueable deps ti=<TaskInstance: first_dag.first_task scheduled__2023-07-10T00:00:00+00:00 [queued]>
[2024-07-03T19:20:59.123+0000] {taskinstance.py:2306} INFO - Starting attempt 1 of 6
[2024-07-03T19:20:59.137+0000] {taskinstance.py:2330} INFO - Executing <Task(BashOperator): first_task> on 2023-07-10 00:00:00+00:00
[2024-07-03T19:20:59.144+0000] {warnings.py:112} WARNING - /home/***/.local/lib/python3.12/site-packages/***/task/task_runner/standard_task_runner.py:61: DeprecationWarning: This process (pid=962) is multi-threaded, use of fork() may lead to deadlocks in the child.
  pid = os.fork()

[2024-07-03T19:20:59.146+0000] {standard_task_runner.py:63} INFO - Started process 972 to run task
[2024-07-03T19:20:59.146+0000] {standard_task_runner.py:90} INFO - Running: ['***', 'tasks', 'run', 'first_dag', 'first_task', 'scheduled__2023-07-10T00:00:00+00:00', '--job-id', '169', '--raw', '--subdir', 'DAGS_FOLDER/first_dag.py', '--cfg-path', '/tmp/tmp84rpje1p']
[2024-07-03T19:20:59.147+0000] {standard_task_runner.py:91} INFO - Job 169: Subtask first_task
[2024-07-03T19:20:59.212+0000] {task_command.py:426} INFO - Running <TaskInstance: first_dag.first_task scheduled__2023-07-10T00:00:00+00:00 [running]> on host 2a6e93921527
[2024-07-03T19:20:59.347+0000] {taskinstance.py:2648} INFO - Exporting env vars: AIRFLOW_CTX_DAG_OWNER='me' AIRFLOW_CTX_DAG_ID='first_dag' AIRFLOW_CTX_TASK_ID='first_task' AIRFLOW_CTX_EXECUTION_DATE='2023-07-10T00:00:00+00:00' AIRFLOW_CTX_TRY_NUMBER='1' AIRFLOW_CTX_DAG_RUN_ID='scheduled__2023-07-10T00:00:00+00:00'
[2024-07-03T19:20:59.348+0000] {taskinstance.py:430} INFO - ::endgroup::
[2024-07-03T19:20:59.361+0000] {subprocess.py:63} INFO - Tmp dir root location: /tmp
[2024-07-03T19:20:59.362+0000] {subprocess.py:75} INFO - Running command: ['/usr/bin/bash', '-c', 'Hello world, this is the first task']
[2024-07-03T19:20:59.375+0000] {subprocess.py:86} INFO - Output:
[2024-07-03T19:20:59.377+0000] {subprocess.py:93} INFO - /usr/bin/bash: line 1: Hello: command not found
[2024-07-03T19:20:59.378+0000] {subprocess.py:97} INFO - Command exited with return code 127
[2024-07-03T19:20:59.378+0000] {taskinstance.py:441} INFO - ::group::Post task execution logs
[2024-07-03T19:20:59.405+0000] {taskinstance.py:2905} ERROR - Task failed with exception
Traceback (most recent call last):
  File "/home/airflow/.local/lib/python3.12/site-packages/airflow/models/taskinstance.py", line 465, in _execute_task
    result = _execute_callable(context=context, **execute_callable_kwargs)
             ^^^^^^^^^^^^^^^^^^^^^^^^^^^^^^^^^^^^^^^^^^^^^^^^^^^^^^^^^^^^^
  File "/home/airflow/.local/lib/python3.12/site-packages/airflow/models/taskinstance.py", line 432, in _execute_callable
    return execute_callable(context=context, **execute_callable_kwargs)
           ^^^^^^^^^^^^^^^^^^^^^^^^^^^^^^^^^^^^^^^^^^^^^^^^^^^^^^^^^^^^
  File "/home/airflow/.local/lib/python3.12/site-packages/airflow/models/baseoperator.py", line 401, in wrapper
    return func(self, *args, **kwargs)
           ^^^^^^^^^^^^^^^^^^^^^^^^^^^
  File "/home/airflow/.local/lib/python3.12/site-packages/airflow/operators/bash.py", line 243, in execute
    raise AirflowException(
airflow.exceptions.AirflowException: Bash command failed. The command returned a non-zero exit code 127.
[2024-07-03T19:20:59.410+0000] {taskinstance.py:1206} INFO - Marking task as UP_FOR_RETRY. dag_id=first_dag, task_id=first_task, run_id=scheduled__2023-07-10T00:00:00+00:00, execution_date=20230710T000000, start_date=20240703T192059, end_date=20240703T192059
[2024-07-03T19:20:59.427+0000] {standard_task_runner.py:110} ERROR - Failed to execute job 169 for task first_task (Bash command failed. The command returned a non-zero exit code 127.; 972)
[2024-07-03T19:20:59.481+0000] {local_task_job_runner.py:240} INFO - Task exited with return code 1
[2024-07-03T19:20:59.505+0000] {local_task_job_runner.py:222} INFO - ::endgroup::
